Workbook

Sheet Japanese
B2: スキルシート（開発エンジニア）
B4: 氏名 | C4: =English!C4 -> Nguyen Thi Thu Huong | G4: 記入日 | H4: 44818
B5: レベルの記載基準
B7: S : 業務上の指導が可能なレベルの経験がある
B8: A : 個人で開発したものを一般に公開した経験がある
B9: B : 業務上の開発・運用を完結できるレベルの経験がある
B10: C : 開発・運用経験がある
B11: D : ごく簡単なアプリケーション（掲示板など）を開発・運用した経験がある / 触った経験がある
B12: 空白 : ほとんど経験無し
B14: スキル | E14: 経験年数 | F14: レベル | G14: スキル | J14: 経験年数 | K14: レベル | L14: スキル | O14: 経験年数 | P14: レベル
B15: 言語 | G15: ライブラリ / フレームワーク | L15: Salesforce
B16: =English!B16 -> C/C++ | E16: =English!E16 -> 0 | F16: =English!F16 -> 0 | G16: =English!G16 -> ReactJS | J16: =English!J16 -> 0 | K16: =English!K16 -> 0 | L16: =English!L16 -> Apex | O16: =English!O16 -> 0 | P16: =English!P16 -> 0
B17: =English!B17 -> Ruby | E17: =English!E17 -> 0 | F17: =English!F17 -> 0 | G17: =English!G17 -> NextJS | J17: =English!J17 -> 0 | K17: =English!K17 -> 0 | L17: =English!L17 -> Visualforce | O17: =English!O17 -> 0 | P17: =English!P17 -> 0
B18: =English!B18 -> Objective-C | E18: =English!E18 -> 0 | F18: =English!F18 -> 0 | G18: =English!G18 -> ReactNative | J18: =English!J18 -> 0 | K18: =English!K18 -> 0 | L18: =English!L18 -> Lightning component | O18: =English!O18 -> 0 | P18: =English!P18 -> 0
B19: =English!B19 -> C# | E19: =English!E19 -> 0 | F19: =English!F19 -> 0 | G19: =English!G19 -> AngularJS | J19: =English!J19 -> 0 | K19: =English!K19 -> 0 | L19: =English!L19 -> Sales Cloud | O19: =English!O19 -> 0 | P19: =English!P19 -> 0
B20: =English!B20 -> Python | E20: =English!E20 -> 0 | F20: =English!F20 -> 0 | G20: =English!G20 -> NodeJS | J20: =English!J20 -> 0 | K20: =English!K20 -> 0 | L20: =English!L20 -> Service Cloud | O20: =English!O20 -> 0 | P20: =English!P20 -> 0
B21: =English!B21 -> PHP | E21: =English!E21 -> 0 | F21: =English!F21 -> 0 | G21: =English!G21 -> VueJS | J21: =English!J21 -> 0 | K21: =English!K21 -> 0 | L21: =English!L21 -> Marketing Cloud | O21: =English!O21 -> 0 | P21: =English!P21 -> 0
B22: =English!B22 -> Java | E22: =English!E22 -> 0 | F22: =English!F22 -> 0 | G22: =English!G22 -> NuxtJS | J22: =English!J22 -> 0 | K22: =English!K22 -> 0 | L22: =English!L22 -> Commerce Cloud | O22: =English!O22 -> 0 | P22: =English!P22 -> 0
B23: =English!B23 -> Kotlin | E23: =English!E23 -> 0 | F23: =English!F23 -> 0 | G23: =English!G23 -> Ionic & Cordova | J23: =English!J23 -> 0 | K23: =English!K23 -> 0 | L23: =English!L23 -> Experience Cloud | O23: =English!O23 -> 0 | P23: =English!P23 -> 0
B24: =English!B24 -> Groovy | E24: =English!E24 -> 0 | F24: =English!F24 -> 0 | G24: =English!G24 -> .NET Framework | J24: =English!J24 -> 0 | K24: =English!K24 -> 0 | L24: =English!L24 -> App Cloud | O24: =English!O24 -> 0 | P24: =English!P24 -> 0
B25: =English!B25 -> ActionScript | E25: =English!E25 -> 0 | F25: =English!F25 -> 0 | G25: =English!G25 -> WPF | J25: =English!J25 -> 0 | K25: =English!K25 -> 0 | L25: =English!L25 -> Integration | O25: =English!O25 -> 0 | P25: =English!P25 -> 0
B26: =English!B26 -> JavaScript | E26: =English!E26 -> 0 | F26: =English!F26 -> 0 | G26: =English!G26 -> Ruby on Rails | J26: =English!J26 -> 0 | K26: =English!K26 -> 0 | L26: クラウドサービス
B27: =English!B27 -> TypeScript | E27: =English!E27 -> 0 | F27: =English!F27 -> 0 | G27: =English!G27 -> Zend Framework | J27: =English!J27 -> 0 | K27: =English!K27 -> 0 | L27: =English!L27 -> Firebase | O27: =English!O27 -> 0 | P27: =English!P27 -> 0
B28: =English!B28 -> Golang | E28: =English!E28 -> 0 | F28: =English!F28 -> 0 | G28: =English!G28 -> CakePHP | J28: =English!J28 -> 0 | K28: =English!K28 -> 0 | L28: =English!L28 -> Amazone Web Service | O28: =English!O28 -> 0 | P28: =English!P28 -> 0
B29: =English!B29 -> Rust | E29: =English!E29 -> 0 | F29: =English!F29 -> 0 | G29: =English!G29 -> Symfony | J29: =English!J29 -> 0 | K29: =English!K29 -> 0 | L29: =English!L29 -> Microsoft Azure | O29: =English!O29 -> 0 | P29: =English!P29 -> 0
B30: =English!B30 -> Solidity | E30: =English!E30 -> 0 | F30: =English!F30 -> 0 | G30: =English!G30 -> Laravel Framework | J30: =English!J30 -> 0 | K30: =English!K30 -> 0 | L30: =English!L30 -> Google Cloud | O30: =English!O30 -> 0 | P30: =English!P30 -> 0
B31: =English!B31 -> Swift | E31: =English!E31 -> 0 | F31: =English!F31 -> 0 | G31: =English!G31 -> Codeigniter | J31: =English!J31 -> 0 | K31: =English!K31 -> 0 | L31: テスト
B32: =English!B32 -> Dart | E32: =English!E32 -> 0 | F32: =English!F32 -> 0 | G32: =English!G32 -> Flask | J32: =English!J32 -> 0 | K32: =English!K32 -> 0 | L32: =English!L32 -> Testcase writing | O32: 0.5 | P32: C
B33: =English!B33 -> Scala | E33: =English!E33 -> 0 | F33: =English!F33 -> 0 | G33: =English!G33 -> Django Framework | J33: =English!J33 -> 0 | K33: =English!K33 -> 0 | L33: =English!L33 -> Test planning | O33: 0.5 | P33: C
B34: =English!B34 -> R | E34: =English!E34 -> 0 | F34: =English!F34 -> 0 | G34: =English!G34 -> BeeGo / Gin Gonic / Kit | J34: =English!J34 -> 0 | K34: =English!K34 -> 0 | L34: =English!L34 -> Unit Testing | O34: 0 | P34: 0
B35: =English!B35 -> HTML5 | E35: =English!E35 -> 0 | F35: =English!F35 -> 0 | G35: =English!G35 -> Struts / JSF | J35: 3 | K35: B | L35: =English!L35 -> Manual Testing | O35: 0.5 | P35: C
B36: =English!B36 -> CSS | E36: =English!E36 -> 0 | F36: =English!F36 -> 0 | G36: =English!G36 -> Spring Framework | J36: =English!J36 -> 0 | K36: =English!K36 -> 0 | L36: =English!L36 -> Automation Testing | O36: =English!O36 -> 0 | P36: =English!P36 -> 0
B37: =English!B37 -> XML | E37: =English!E37 -> 0 | F37: =English!F37 -> 0 | G37: =English!G37 -> Flutter | J37: =English!J37 -> 0 | K37: =English!K37 -> 0 | L37: =English!L37 -> Load Testing | O37: =English!O37 -> 0 | P37: =English!P37 -> 0
B38: データベース | G38: =English!G38 -> Web3j | J38: =English!J38 -> 0 | K38: =English!K38 -> 0 | L38: 管理
B39: S : 自力でボトルネック調査、チューニングができる A : テーブル構造を設計できる B : パフォーマンスを考慮したクエリがかける C : 業務で使用したことがある D : 人の書いたクエリが読める | G39: =English!G39 -> SmartContract (Solana / Ethereum) | J39: =English!J39 -> 0 | K39: =English!K39 -> 0 | L39: =English!L39 -> Technical leader | O39: =English!O39 -> 0 | P39: =English!P39 -> 0
G40: 開発環境 | L40: =English!L40 -> BrSE | O40: =English!O40 -> 0 | P40: =English!P40 -> 0
G41: =English!G41 -> Windows App Development | J41: =English!J41 -> 0 | K41: =English!K41 -> 0 | L41: =English!L41 -> Project manager | O41: =English!O41 -> 0 | P41: =English!P41 -> 0
G42: =English!G42 -> iPhone App Development | J42: =English!J42 -> 0 | K42: =English!K42 -> 0 | L42: 開発プロセス
B43: =English!B43 -> MySQL | E43: =English!E43 -> 0 | F43: =English!F43 -> 0 | G43: =English!G43 -> Android App Development | J43: =English!J43 -> 0 | K43: =English!K43 -> 0 | L43: =English!L43 -> Requirement definition | O43: =English!O43 -> 0 | P43: =English!P43 -> 0
B44: =English!B44 -> PostgreSQL | E44: =English!E44 -> 0 | F44: =English!F44 -> 0 | G44: =English!G44 -> Visual Studio Code | J44: =English!J44 -> 0 | K44: =English!K44 -> 0 | L44: =English!L44 -> Software specification creation | O44: =English!O44 -> 0 | P44: =English!P44 -> 0
...

Sheet English
B2: Skill Sheet (Software Engineer)
B4: Name | C4: Nguyen Thi Thu Huong | G4: Updated date | H4: 44818
B5: Level Description Criteria
B7: S: Ability to instruct others on business and technique, provide system proposal
B8: A: Ability to publish software product to be developed by yourself
B9: B: Ability to develop and operate the whole software product
B10: C: Have experience in developing and operating the software product
B11: D: Have experience in developing a very simple application/ software product
B12: Blank: Have no experience
B14: SKILL | E14: Years Experience | F14: Level | G14: SKILL | J14: Years Experience | K14: Level | L14: SKILL | O14: Years Experience | P14: Level
B15: Language | G15: Library/Framework | L15: Salesforce
B16: C/C++ | G16: ReactJS | L16: Apex
B17: Ruby | G17: NextJS | L17: Visualforce
B18: Objective-C | G18: ReactNative | L18: Lightning component
B19: C# | G19: AngularJS | L19: Sales Cloud
B20: Python | G20: NodeJS | L20: Service Cloud
B21: PHP | G21: VueJS | L21: Marketing Cloud
B22: Java | G22: NuxtJS | L22: Commerce Cloud
B23: Kotlin | G23: Ionic & Cordova | L23: Experience Cloud
B24: Groovy | G24: .NET Framework | L24: App Cloud
B25: ActionScript | G25: WPF | L25: Integration
B26: JavaScript | G26: Ruby on Rails | L26: Cloud Service
... B31: Swift | G31: Codeigniter | L31: Testing Skill
B32: Dart | G32: Flask | L32: Testcase writing | O32: 0.5 | P32: C
B33: Scala | G33: Django Framework | L33: Test planning | O33: 0.5 | P33: C
B34: R | G34: BeeGo / Gin Gonic / Kit | L34: Unit Testing
B35: HTML5 | G35: Struts / JSF | L35: Manual Testing | O35: 0.5 | P35: C
B36: CSS | G36: Spring Framework | L36: Automation Testing
B37: XML | G37: Flutter | L37: Load Testing
B38: Database | G38: Web3j | L38: Management Skill
B39: S: Ability to resolve bottleneck A: Ability to design database B: Ability to execute query with high performance C: Have experience in using DB D: Ability to read queries written by others | G39: SmartContract (Solana / Ethereum) | L39: Technical leader
G40: Development Environment | L40: BrSE
G41: Windows App Development | L41: Project manager
G42: iPhone App Development | L42: Development Process
B43: MySQL | G43: Android App Development | L43: Requirement definition
B44: PostgreSQL | G44: Visual Studio Code | L44: Software specification creation
B45: Oracle | G45: Visual Studio | L45: RDBMS design
B46: Sqlite | G46: Eclipse | L46: TDD / BDD
B47: Realm | G47: IntelliJ | L47: Waterfall
B48: Core Data | G48: PyCharm | L48: SCRUM / Agile development | O48: 0.5 | P48: D
...
